<?xml version="1.0" ?>
<!-- =================================================================================== -->
<!-- |    This document was autogenerated by xacro from mycobot_280_arm_matlab.urdf.xacro | -->
<!-- |    EDITING THIS FILE BY HAND IS NOT RECOMMENDED                                 | -->
<!-- =================================================================================== -->
<robot name="mycobot_280">
  <link name="world"/>
  <link name="base_link"/>
  <joint name="virtual_joint" type="fixed">
    <parent link="world"/>
    <child link="base_link"/>
    <origin rpy="0 0 0" xyz="0 0 0"/>
  </joint>
  <link name="link1">
    <inertial>
      <origin rpy="0 0 0" xyz="0 0 0.0"/>
      <mass value="0.12"/>
      <inertia ixx="0.000148" ixy="0.0" ixz="0.0" iyy="0.000148" iyz="0.0" izz="9.6e-05"/>
    </inertial>
    <visual>
      <geometry>
        <mesh filename="file:///home/gugu/gugu_workspace/mycobot_ros2/install/mycobot_description/share/mycobot_description/meshes/mycobot_280/visual/link1.dae"/>
        <!-- <mesh filename="file://C:/Users/liang/Documents/MATLAB/IK_solve/mycobot_description/meshes/link1.dae"/> -->
      </geometry>
      <origin rpy="0 0 -1.5707963267948966" xyz="0.0 0 0"/>
    </visual>
    <collision>
      <geometry>
        <box size="0.08 0.12 0.075"/>
      </geometry>
      <origin rpy="0 0 0" xyz="0.0 -0.01 0.034"/>
    </collision>
  </link>
  <link name="link2">
    <inertial>
      <origin rpy="0 0 0" xyz="0 0 0.0"/>
      <mass value="0.19"/>
      <inertia ixx="0.000148" ixy="0.0" ixz="0.0" iyy="0.000148" iyz="0.0" izz="9.6e-05"/>
    </inertial>
    <visual>
      <geometry>
        <mesh filename="file:///home/gugu/gugu_workspace/mycobot_ros2/install/mycobot_description/share/mycobot_description/meshes/mycobot_280/visual/link2.dae"/>
      </geometry>
      <origin rpy="0 0 -1.5707963267948966" xyz="0.0 0 -0.06096"/>
    </visual>
    <collision>
      <geometry>
        <cylinder length="0.085" radius="0.025"/>
      </geometry>
      <origin rpy="0 0 -1.5707963267948966" xyz="0.0 0 -0.02"/>
    </collision>
  </link>
  <link name="link3">
    <inertial>
      <origin rpy="0 0 0" xyz="0 0 0.0"/>
      <mass value="0.16"/>
      <inertia ixx="0.000148" ixy="0.0" ixz="0.0" iyy="0.000148" iyz="0.0" izz="9.6e-05"/>
    </inertial>
    <visual>
      <geometry>
        <mesh filename="file:///home/gugu/gugu_workspace/mycobot_ros2/install/mycobot_description/share/mycobot_description/meshes/mycobot_280/visual/link3.dae"/>
      </geometry>
      <origin rpy="0 -1.5707963267948966 0" xyz="0.0 0 0.03256"/>
    </visual>
    <collision>
      <geometry>
        <cylinder length="0.15" radius="0.025"/>
      </geometry>
      <origin rpy="0 -1.5707963267948966 0" xyz="-0.058 0 0.059"/>
    </collision>
  </link>
  <link name="link4">
    <inertial>
      <origin rpy="0 0 0" xyz="0 0 0.0"/>
      <mass value="0.124"/>
      <inertia ixx="0.000103" ixy="0.0" ixz="0.0" iyy="0.000103" iyz="0.0" izz="9.6e-05"/>
    </inertial>
    <visual>
      <geometry>
        <mesh filename="file:///home/gugu/gugu_workspace/mycobot_ros2/install/mycobot_description/share/mycobot_description/meshes/mycobot_280/visual/link4.dae"/>
      </geometry>
      <origin rpy="0 -1.5707963267948966 0" xyz="0.0 0 0.03056"/>
    </visual>
    <collision>
      <geometry>
        <cylinder length="0.125" radius="0.025"/>
      </geometry>
      <origin rpy="0 -1.5707963267948966 0" xyz="-0.05 0 0.0"/>
    </collision>
  </link>
  <link name="link5">
    <inertial>
      <origin rpy="0 0 0" xyz="0 0 0.0"/>
      <mass value="0.11"/>
      <inertia ixx="0.000103" ixy="0.0" ixz="0.0" iyy="0.000103" iyz="0.0" izz="9.6e-05"/>
    </inertial>
    <visual>
      <geometry>
        <mesh filename="file:///home/gugu/gugu_workspace/mycobot_ros2/install/mycobot_description/share/mycobot_description/meshes/mycobot_280/visual/link5.dae"/>
      </geometry>
      <origin rpy="-1.5707963267948966 0 0" xyz="0.0 0 -0.03356"/>
    </visual>
    <collision>
      <geometry>
        <box size="0.03 0.035 0.05"/>
      </geometry>
      <origin rpy="0 0.0 0" xyz="0.0 0 -0.005"/>
    </collision>
  </link>
  <link name="link6">
    <inertial>
      <origin rpy="0 0 0" xyz="0 0 0.0"/>
      <mass value="0.0739"/>
      <inertia ixx="6.649e-05" ixy="0.0" ixz="0.0" iyy="6.649e-05" iyz="0.0" izz="9.6e-05"/>
    </inertial>
    <visual>
      <geometry>
        <mesh filename="file:///home/gugu/gugu_workspace/mycobot_ros2/install/mycobot_description/share/mycobot_description/meshes/mycobot_280/visual/link6.dae"/>
      </geometry>
      <origin rpy="0 0 0" xyz="0 0.00 -0.038"/>
    </visual>
    <collision>
      <geometry>
        <cylinder length="0.06" radius="0.025"/>
      </geometry>
      <origin rpy="-1.5707963267948966 0 0" xyz="0 0.00 0.0"/>
    </collision>
  </link>
  <link name="link6_flange">
    <inertial>
      <origin rpy="0 0 0" xyz="0 0 0.0"/>
      <mass value="0.035"/>
      <inertia ixx="1.49e-05" ixy="0.0" ixz="0.0" iyy="1.49e-05" iyz="0.0" izz="1.96e-05"/>
    </inertial>
    <visual>
      <geometry>
        <mesh filename="file:///home/gugu/gugu_workspace/mycobot_ros2/install/mycobot_description/share/mycobot_description/meshes/mycobot_280/visual/link7.dae"/>
      </geometry>
      <origin rpy="0 0 0" xyz="0.0 0 -0.012"/>
    </visual>
    <collision>
      <geometry>
        <cylinder length="0.02" radius="0.02"/>
      </geometry>
      <origin rpy="0 0 0" xyz="0 0.00 0.0"/>
    </collision>
  </link>
  <joint name="base_link_to_link1" type="fixed">
    <parent link="base_link"/>
    <child link="link1"/>
    <origin rpy="0 0 0" xyz="0 0 0"/>
  </joint>
  <joint name="link1_to_link2" type="revolute">
    <axis xyz="0 0 1"/>
    <limit effort="56.0" lower="-2.879793" upper="2.879793" velocity="2.792527"/>
    <parent link="link1"/>
    <child link="link2"/>
    <origin rpy="0 0 1.5707963267948966" xyz="0 0 0.13156"/>
    <dynamics damping="0.0" friction="0.0"/>
  </joint>
  <joint name="link2_to_link3" type="revolute">
    <axis xyz="0 0 1"/>
    <limit effort="56.0" lower="-2.879793" upper="2.879793" velocity="2.792527"/>
    <parent link="link2"/>
    <child link="link3"/>
    <origin rpy="0 1.5707963267948966 -1.5707963267948966" xyz="0 0 -0.001"/>
    <dynamics damping="0.0" friction="0.0"/>
  </joint>
  <joint name="link3_to_link4" type="revolute">
    <axis xyz="0 0 1"/>
    <limit effort="56.0" lower="-2.879793" upper="2.879793" velocity="2.792527"/>
    <parent link="link3"/>
    <child link="link4"/>
    <origin rpy="0 0 0" xyz="-0.1104 0 0"/>
    <dynamics damping="0.0" friction="0.0"/>
  </joint>
  <joint name="link4_to_link5" type="revolute">
    <axis xyz="0 0 1"/>
    <limit effort="56.0" lower="-2.879793" upper="2.879793" velocity="2.792527"/>
    <parent link="link4"/>
    <child link="link5"/>
    <origin rpy="0 0 -1.5707963267948966" xyz="-0.096 0 0.06062"/>
    <dynamics damping="0.0" friction="0.0"/>
  </joint>
  <joint name="link5_to_link6" type="revolute">
    <axis xyz="0 0 1"/>
    <limit effort="56.0" lower="-2.879793" upper="2.879793" velocity="2.792527"/>
    <parent link="link5"/>
    <child link="link6"/>
    <origin rpy="1.5707963267948966 -1.5707963267948966 0" xyz="0 -0.07318 0"/>
    <dynamics damping="0.0" friction="0.0"/>
  </joint>
  <joint name="link6_to_link6_flange" type="revolute">
    <axis xyz="0 0 1"/>
    <limit effort="56.0" lower="-3.05" upper="3.05" velocity="2.792527"/>
    <parent link="link6"/>
    <child link="link6_flange"/>
    <origin rpy="-1.5707963267948966 0 0" xyz="0 0.0456 0"/>
    <dynamics damping="0.0" friction="0.0"/>
  </joint>
  <gazebo reference="link1">
    <visual>
      <material>
        <ambient>0.5 0.5 0.5 1</ambient>
        <diffuse>0.5 0.5 0.5 1</diffuse>
        <specular>0.5 0.5 0.5 1</specular>
      </material>
    </visual>
  </gazebo>
  <gazebo reference="link2">
    <visual>
      <material>
        <ambient>1 1 1 1</ambient>
        <diffuse>1 1 1 1</diffuse>
        <specular>1 1 1 1</specular>
      </material>
    </visual>
  </gazebo>
  <gazebo reference="link3">
    <visual>
      <material>
        <ambient>1 1 1 1</ambient>
        <diffuse>1 1 1 1</diffuse>
        <specular>1 1 1 1</specular>
      </material>
    </visual>
  </gazebo>
  <gazebo reference="link4">
    <visual>
      <material>
        <ambient>1 1 1 1</ambient>
        <diffuse>1 1 1 1</diffuse>
        <specular>1 1 1 1</specular>
      </material>
    </visual>
  </gazebo>
  <gazebo reference="link5">
    <visual>
      <material>
        <ambient>1 1 1 1</ambient>
        <diffuse>1 1 1 1</diffuse>
        <specular>1 1 1 1</specular>
      </material>
    </visual>
  </gazebo>
  <gazebo reference="link6">
    <visual>
      <material>
        <ambient>1 1 1 1</ambient>
        <diffuse>1 1 1 1</diffuse>
        <specular>1 1 1 1</specular>
      </material>
    </visual>
  </gazebo>
  <gazebo reference="link6_flange">
    <visual>
      <material>
        <ambient>0.5 0.5 0.5 1</ambient>
        <diffuse>0.5 0.5 0.5 1</diffuse>
        <specular>0.5 0.5 0.5 1</specular>
      </material>
    </visual>
  </gazebo>
</robot>
